<!DOCTYPE html>
<html lang="en">
<head>
	<meta charset="UTF-8">
	<title>Promise</title>
	<script>
		//ES6规定，Promise对象是一个构造函数，用来生成Promise实例;Promise有三种状态：pending,refilled(resolved),rejected
		//举一个简单的栗子
		function timeout(_ms){
			return new Promise((resolve,reject) => {
				setTimeout(resolve,_ms,'done');
				//setTimeout(reject,_ms,'failed');
			});
		};
		timeout(100).then((value) => {
			console.log(value);//done
		});
		// timeout(100).catch((value) => {
		// 	console.log(value);
		// });

		const p1 = new Promise((resolve,reject) => {
			setTimeout(() => reject(new Error('fail')),3000);
		});
		const p2 = new Promise((resolve,reject) => {
			console.log(p1);//Pormise {<pending>}
			setTimeout(() => resolve(p1),1000);
		});
		//p2状态无效，所以无法执行then
		p2.then(result => console.log(result)).catch(error => console.log(error));

		//异步加载图片的fn
		function loadImageAsync(_url){
			return new Promise((resolve,reject) => {
				const image = new Image();

				image.onload = () => {resolve(image)};
				image.onerror = () => {reject(new Error('load image fail' + _url))};

				image.src = _url;
			});
		}

		const url = 'images/fafa.jpg';
		let promise = loadImageAsync(url);
		promise.then(result => console.log(result)).catch(error => console.log(error));

		//.then .catch 属于Promise原型对象上的方法,其作用是为 Promise 实例添加状态改变时的回调函数
		//Promise.prototype.catch = Promise.prototype.then(null,rejection) = Promise.prototype.then(undefined,rejection)

		//模拟一个promise抛出异常的写法：
		const errorPormise = new Promise((resolve,reject) => {
			try{//等价
				throw new Error('fail');
			}catch(e){
				reject(e);
			}
			//reject(new Error('fail'));//等价 reject的作用等同于抛除异常
			//throw new Error('fail');//等价
		});

		errorPormise.catch(value => {console.log(value)});

		const rePromise = new Promise((resolve,reject) => {
			resolve('done');
			throw new Error('fail');
		});

		//如果Promise 状态已经变成resolved，再抛出错误是无效的；Promise 的状态一旦改变，就永久保持该状态，不会再变了；
		rePromise.then(result => console.log(result)).catch(error => console.log(error));
		
		//Promise 内部的错误不会影响到 Promise 外部的代码
		const innerPromise = new Promise((resolve,reject) => {
			resolve(x+2);//ReferenceError: x is not defined
		});

		innerPromise.then(result => console.log(result)).catch(error => console.log(error));
		setTimeout(() => {console.log('filled');},1000);//正常输出filled

		//可以执行第二个catch去捕获第一个catch留下来的错误
		const secondPromise = new Promise((resolve,reject) => {
			reject(new Error('fail'));
		});
		
		secondPromise.catch(error => {
			console.log(error);
			y+2;
		}).catch(error => console.log(error));//ReferenceError: y is not defined


		//Promise finally，本质上是then的特例,finally不接受任何参数
		//promise.finally(() => {...});//等同于下面
		// promise.then(
		// 	result => {return result;},
		// 	error => {throw error;}
		// 	);
		//finally实现的原理：
		// Promise.prototype.finally = function(callBack){
		// 	let P = this.constructor;//Promise.prototype.constructor = Promise
		// 	return this.then(
		// 		value => P.resolve(callBack()).then(() => value),
		// 		resaon => P.resole(callBack()).then(() => {throw resaon})
		// 		);
		// };
		
		//Promise.prototype.all:将多个 Promise 实例，包装成一个新的 Promise 实例;特点：all([p1,p2,p3,...])只有p1p2p3等所有promise实例状态为resolved或者有一个实例比如p1状态为rejected，那么Promise的状态就为resolved或者rejected;
		const p3 = new Promise((resolve,reject) => {
			resolve('all success');
		}).then(result => result).catch(error => error);

		const p4 = new Promise((resolve,reject) => {
			throw new Error('all fail');
		}).then(result => result).catch(error => error);

		Promise.all([p3,p4]).then(result => console.log(result)).catch(error => console.log(error));
		
		//Promise.prototype.race:将多个 Promise 实例，包装成一个新的 Promise 实例;特点：只要p1p2p3中有一个实例率先改变状态，p的状态就跟着改变
		//const p = Promise.race([p1, p2, p3]);
		
		const p = Promise.race([
			fetch('/resource-that-may-take-a-while'),//Fetch API cannot load file:///D:/resource-that-may-take-a-while
			new Promise((resolve,reject) => {
				setTimeout(() => reject(new Error('request timeout')),5000);
			})
			]);
		p.then(result => console.log(result)).catch(error => console.log(error));//走catch

		//Promise.resolve(_param):将对象转化为Promise对象
		//Promise.resolve('foo');//等同于 new Promise(resolve => resolve('foo'));
		//1._param为Promise实例，则原封不动返回该实例;
		//2._param为具有then方法的对象，俗称thenable，然后直接执行该对象里面的then方法；
		let thenable = {
			then:function(resolve,reject){
				resolve('thenable');
			}
		};

		let p5 = Promise.resolve(thenable);
		p5.then(result => console.log(result));
		//3._param不具有then方法，同时也不是一个对象:则Promise.resolve方法返回一个新的 Promise 对象，状态为resolved
		
		const p6 = Promise.resolve('hello');
		p6.then(result => console.log(result));
		//4.不带任何参数
		let p7 = Promise.resolve();//直接返回一个resolved状态的 Promise 对象
		p7.then(() => console.log('no param'));

		//5.注意：立即Promise.resolve()出来的Promise对象在then时是在当前最后执行的，但是要比定时器要快些；
		//本轮事件循环的末尾:如下面正常执行的三个语句，在执行console.log(1)之后
		setTimeout(function(){
			console.log('setTimeout');
		},0);
		Promise.resolve().then(() => console.log('测试时序'));
		console.log(1);
		//1
		//测试时序
		//setTimeout

		//Promise.reject(reason):方法也会返回一个新的 Promise 实例，该实例的状态为rejected。
		//reason参数:会原封不动地作为reject的理由，变成后续方法的参数;
		// const p8 = Promise.reject('出错了');
		// p8.catch(result => console.log(result));//等同于下面
		const p9 = new Promise((resolve,reject) => reject('reject 等价于上面的 出错了'));
		p9.catch(result => console.log(result));
	</script>
</head>
<body>
</body>
</html>